Workbook

Sheet Summary
A1: DM-32UV settings check: dm32.bin vs QDMR vs factory CPS
A2: Built from the analysis in this chat. Nothing here has been tested on a radio.
A4: Counts
A5: Match | B5: =COUNTIF(Comparison!$K$5:$K$90,"Match") -> 57
A6: Differs | B6: =COUNTIF(Comparison!$K$5:$K$90,"Differs") -> 12
A7: Unverified | B7: =COUNTIF(Comparison!$K$5:$K$90,"Unverified") -> 2
A8: Not compared | B8: =COUNTIF(Comparison!$K$5:$K$90,"Not compared") -> 15
A9: Total settings listed | B9: =SUM(B5:B8) -> 86
A10: Share of compared settings that match | B10: =B5/(B5+B6+B7) -> 0.8028169
A12: Main findings
A13: 1. The dump is a DfuSe file; the general settings are at address 0x4000. Most settings match the factory CPS values when read with QDMR's offsets (see the counts above).
A14: 2. TOT and Active Wait Time: QDMR reads one step higher than the factory CPS (125 s vs 120 s, 660 ms vs 630 ms).
A15: 3. VOX Level, both mic levels and brightness: the factory CPS shows raw + 1. QDMR rescales the mic levels and brightness to a 1-10 scale, and reads VOX raw 0 as "off".
A16: 4. GPS switch, GPS mode, time zone, Work Mode A/B and Main Channel: QDMR's reading differs from the factory display (see the Differences sheet).
A17: 5. Round trip: for the values QDMR both reads and writes (TOT, VOX, mic levels) the raw byte comes back unchanged (see the Round trip sheet).
A19: Sources and assumptions
A20: - Raw bytes: your dm32.bin (394,285 bytes), element at address 0x4000 (4,096 bytes).
A21: - Offsets and QDMR's decoding rules: QDMR source, lib/dm32uv_codeplug.hh and dm32uv_codeplug.cc (GeneralSettingsElement).
A22: - Factory CPS values: read from your 12 Optional Features screenshots.
A23: - Assumption: the factory CPS file and the radio dump describe the same radio state. The many matching values (see the counts above) suggest they do, but this is not proven.
A24: - Candidate factory rules on the Differences sheet are fitted to one data point each. A second dump with a different value would confirm or reject them.
... A30: - Round trip: whether QDMR changes the value when it reads and writes it back.

Sheet Comparison
A1: DM-32UV general settings: raw bytes in dm32.bin vs QDMR vs factory CPS
A2: Offsets are within the general settings block at address 0x4000 of dm32.bin (DfuSe file). Field value is calculated from the raw byte with the bit position and width shown. Result is my judgment from comparing the QDMR reading with the factory screenshot values.
A4: Factory tab | B4: Factory setting | C4: QDMR field | D4: Byte offset (hex) | E4: Bit | F4: Width (bits) | G4: Raw byte (hex) | H4: Field value | I4: QDMR reads as | J4: Factory CPS shows | K4: Result | L4: Note
A5: Power on/off | B5: Auto Power Off | C5: autoPowerOffDelay | D5: 0x1E | E5: 0 | F5: 8 | G5: 00 | H5: =MOD(INT(HEX2DEC(G5)/2^E5),2^F5) -> 0 | I5: Off | J5: Off | K5: Match
A6: Power on/off | B6: Power On Interface | C6: bootDisplay | D6: 0x00 | E6: 0 | F6: 8 | G6: 00 | H6: =MOD(INT(HEX2DEC(G6)/2^E6),2^F6) -> 0 | I6: Image | J6: Power On Picture | K6: Match
A7: Power on/off | B7: Power On Display Line 1 | C7: bootMessage1 | D7: 0x01 | E7: 0 | F7: text | G7: — | H7: — | I7: Welcome | J7: Welcome | K7: Match | L7: Text field, 14 characters; read from the dump as text.
A8: Power on/off | B8: Power On Display Line 2 | C8: bootMessage2 | D8: 0x0F | E8: 0 | F8: text | G8: — | H8: — | I8: DM-32UV | J8: DM-32UV | K8: Match | L8: Text field, 14 characters; read from the dump as text.
A9: Power on/off | B9: Allow Reset | C9: mcuReset | D9: 0x1D | E9: 0 | F9: 8 | G9: 01 | H9: =MOD(INT(HEX2DEC(G9)/2^E9),2^F9) -> 1 | I9: Checked | J9: Checked | K9: Match
A10: Alert Tone | B10: Analog Roger Tone | C10: fmRogerTone | D10: 0x21 | E10: 1 | F10: 2 | G10: 40 | H10: =MOD(INT(HEX2DEC(G10)/2^E10),2^F10) -> 0 | I10: Off | J10: Off | K10: Match
A11: Alert Tone | B11: Radio Silent | C11: radioSilent | D11: 0x20 | E11: 7 | F11: 1 | G11: 3E | H11: =MOD(INT(HEX2DEC(G11)/2^E11),2^F11) -> 0 | I11: Unchecked | J11: Unchecked | K11: Match
A12: Alert Tone | B12: Key Tone | C12: keyTone | D12: 0x20 | E12: 6 | F12: 1 | G12: 3E | H12: =MOD(INT(HEX2DEC(G12)/2^E12),2^F12) -> 0 | I12: Unchecked | J12: Unchecked | K12: Match
A13: Alert Tone | B13: SMS Alert | C13: smsTone | D13: 0x20 | E13: 5 | F13: 1 | G13: 3E | H13: =MOD(INT(HEX2DEC(G13)/2^E13),2^F13) -> 1 | I13: Checked | J13: Checked | K13: Match
A14: Alert Tone | B14: Group Call Tone | C14: groupCallTone | D14: 0x20 | E14: 4 | F14: 1 | G14: 3E | H14: =MOD(INT(HEX2DEC(G14)/2^E14),2^F14) -> 1 | I14: Checked | J14: Checked | K14: Match | L14: Not exported to the YAML by QDMR.
A15: Alert Tone | B15: Private Call Tone | C15: privateCallTone | D15: 0x20 | E15: 3 | F15: 1 | G15: 3E | H15: =MOD(INT(HEX2DEC(G15)/2^E15),2^F15) -> 1 | I15: Checked | J15: Checked | K15: Match
A16: Alert Tone | B16: Call End Tone | C16: eotTone | D16: 0x20 | E16: 2 | F16: 1 | G16: 3E | H16: =MOD(INT(HEX2DEC(G16)/2^E16),2^F16) -> 1 | I16: Checked | J16: Checked | K16: Match
A17: Alert Tone | B17: Talk Permit Tone | C17: talkPermitTone | D17: 0x20 | E17: 1 | F17: 1 | G17: 3E | H17: =MOD(INT(HEX2DEC(G17)/2^E17),2^F17) -> 1 | I17: Checked | J17: Checked | K17: Match
A18: Alert Tone | B18: StartUp Sound | C18: bootTone | D18: 0x20 | E18: 0 | F18: 1 | G18: 3E | H18: =MOD(INT(HEX2DEC(G18)/2^E18),2^F18) -> 0 | I18: Unchecked | J18: Unchecked | K18: Match
A19: Alert Tone | B19: Voice Prompt | C19: voicePrompt | D19: 0x21 | E19: 7 | F19: 1 | G19: 40 | H19: =MOD(INT(HEX2DEC(G19)/2^E19),2^F19) -> 0 | I19: Unchecked | J19: Unchecked | K19: Match
A20: Alert Tone | B20: Battery Low | C20: lowBatteryTone | D20: 0x21 | E20: 6 | F20: 1 | G20: 40 | H20: =MOD(INT(HEX2DEC(G20)/2^E20),2^F20) -> 1 | I20: Checked | J20: Checked | K20: Match | L20: Not exported to the YAML by QDMR.
A21: Display | B21: Volume Change Prompt | C21: showVolumeChange | D21: 0x33 | E21: 4 | F21: 1 | G21: 19 | H21: =MOD(INT(HEX2DEC(G21)/2^E21),2^F21) -> 1 | I21: Checked | J21: Checked | K21: Match
A22: Display | B22: Time Display | C22: showClock | D22: 0x33 | E22: 0 | F22: 1 | G22: 19 | H22: =MOD(INT(HEX2DEC(G22)/2^E22),2^F22) -> 1 | I22: Checked | J22: Checked | K22: Match
A23: Display | B23: Date Display Format | C23: dateFormat | D23: 0x33 | E23: 3 | F23: 1 | G23: 19 | H23: =MOD(INT(HEX2DEC(G23)/2^E23),2^F23) -> 1 | I23: DD/MM/YYYY | J23: d/m/yyy | K23: Match | L23: Factory label has a typo (yyy).
A24: Display | B24: Backlight Brightness | C24: displayBrightness | D24: 0x30 | E24: 0 | F24: 8 | G24: 04 | H24: =MOD(INT(HEX2DEC(G24)/2^E24),2^F24) -> 4 | I24: 8 (scale 1-10) | J24: 5 | K24: Differs | L24: See Differences sheet.
A25: Display | B25: Auto Backlight Duration | C25: backlightDuration | D25: 0x31 | E25: 0 | F25: 8 | G25: 01 | H25: =MOD(INT(HEX2DEC(G25)/2^E25),2^F25) -> 1 | I25: 5 s | J25: 5 s | K25: Match
A26: Display | B26: Menu Exit Time[s] | C26: menuDuration | D26: 0x32 | E26: 0 | F26: 8 | G26: 02 | H26: =MOD(INT(HEX2DEC(G26)/2^E26),2^F26) -> 2 | I26: 10 s | J26: 10 | K26: Match
A27: Display | B27: Call Display Color | C27: callColor | D27: 0x34 | E27: 0 | F27: 8 | G27: 06 | H27: =MOD(INT(HEX2DEC(G27)/2^E27),2^F27) -> 6 | I27: Cyan | J27: Cyan | K27: Match
A28: Display | B28: Standby Character Color | C28: standbyColor | D28: 0x35 | E28: 0 | F28: 8 | G28: 05 | H28: =MOD(INT(HEX2DEC(G28)/2^E28),2^F28) -> 5 | I28: Green | J28: Green | K28: Match
A29: Display | B29: A Channel Name Color | C29: channelNameAColor | D29: 0x38 | E29: 0 | F29: 8 | G29: 02 | H29: =MOD(INT(HEX2DEC(G29)/2^E29),2^F29) -> 2 | I29: Orange | J29: Orange | K29: Match
A30: Display | B30: B Channel Name Color | C30: channelNameBColor | D30: 0x39 | E30: 0 | F30: 8 | G30: 04 | H30: =MOD(INT(HEX2DEC(G30)/2^E30),2^F30) -> 4 | I30: Yellow | J30: Yellow | K30: Match
A31: Display | B31: Zone A Color | C31: zoneNameAColor | D31: 0x3A | E31: 0 | F31: 8 | G31: 07 | H31: =MOD(INT(HEX2DEC(G31)/2^E31),2^F31) -> 7 | I31: Blue | J31: Blue | K31: Match
A32: Display | B32: Zone B Color | C32: zoneNameBColor | D32: 0x3B | E32: 0 | F32: 8 | G32: 03 | H32: =MOD(INT(HEX2DEC(G32)/2^E32),2^F32) -> 3 | I32: Red | J32: Red | K32: Match | L32: Factory label reads "Read"; taken to be Red.
A33: GPS | B33: GPS Switch | C33: enableGNSS | D33: 0x40 | E33: 0 | F33: 1 | G33: 49 | H33: =MOD(INT(HEX2DEC(G33)/2^E33),2^F33) -> 1 | I33: Checked | J33: Unchecked | K33: Differs | L33: See Differences sheet.
A34: GPS | B34: GPS Mode | C34: gnssMode | D34: 0x40 | E34: 3 | F34: 2 | G34: 49 | H34: =MOD(INT(HEX2DEC(G34)/2^E34),2^F34) -> 1 | I34: Beidou | J34: GPS+BDS | K34: Differs | L34: See Differences sheet.
A35: GPS | B35: Time Zone | C35: timeZone | D35: 0x41 | E35: 0 | F35: 8 | G35: 14 | H35: =MOD(INT(HEX2DEC(G35)/2^E35),2^F35) -> 20 | I35: UTC+9:00 | J35: UTC +8:00 | K35: Differs | L35: See Differences sheet.
A36: GPS | B36: Measure Period Interval[s] | C36: posUpdatePeriod | D36: 0x42 | E36: 0 | F36: 8 | G36: 05 | H36: =MOD(INT(HEX2DEC(G36)/2^E36),2^F36) -> 5 | I36: 5 min | J36: 5 | K36: Unverified | L36: Same number; QDMR calls the unit minutes, the factory label says seconds.
A37: GPS | B37: GPS Display Format | C37: positionFormat | D37: 0x40 | E37: 6 | F37: 1 | G37: 49 | H37: =MOD(INT(HEX2DEC(G37)/2^E37),2^F37) -> 1 | I37: Degree/Min/Sec | J37: Degree/Min/Sec | K37: Match
A38: Record | B38: Record Switch | C38: enableRecording | D38: 0x45 | E38: 0 | F38: 1 | G38: 00 | H38: =MOD(INT(HEX2DEC(G38)/2^E38),2^F38) -> 0 | I38: Unchecked | J38: Unchecked | K38: Match
A39: Record | B39: Record Type | C39: recordMode | D39: 0x43 | E39: 2 | F39: 2 | G39: 00 | H39: =MOD(INT(HEX2DEC(G39)/2^E39),2^F39) -> 0 | I39: Receive | J39: Receive Record | K39: Match
A40: Digital | B40: Call Hold Time[s] | C40: dmrCallHangTime | D40: 0x61 | E40: 0 | F40: 8 | G40: 04 | H40: =MOD(INT(HEX2DEC(G40)/2^E40),2^F40) -> 4 | I40: 2.0 s | J40: 2.0 | K40: Match
A41: Digital | B41: Active Wait Time[ms] | C41: activeWaitTime | D41: 0x62 | E41: 0 | F41: 8 | G41: 0C | H41: =MOD(INT(HEX2DEC(G41)/2^E41),2^F41) -> 12 | I41: 660 ms | J41: 630 | K41: Differs | L41: See Differences sheet.
...

Sheet Differences
A1: Where QDMR and the factory CPS disagree
A2: Numeric settings: the QDMR rule and a candidate factory rule are both calculated from the raw value. The candidate rules are fitted to this one dump (one data point each) and are NOT confirmed.
A4: Setting | B4: Raw value | C4: QDMR rule | D4: QDMR result | E4: Factory CPS shows | F4: Candidate factory rule | G4: Candidate result | H4: Candidate matches? | I4: Note
A5: TOT[s] | B5: =Comparison!H67 -> 22 | C5: raw x 5 + 15 (0 = off) | D5: =IF(B5=0,"Off",B5*5+15) -> 125 | E5: 120 | F5: (raw - 1) x 5 + 15 | G5: =(B5-1)*5+15 -> 120 | H5: =IF(G5=E5,"yes","no") -> yes | I5: QDMR is one step higher than the factory CPS.
A6: Active Wait Time[ms] | B6: =Comparison!H41 -> 12 | C6: raw x 30 + 300 | D6: =B6*30+300 -> 660 | E6: 630 | F6: (raw - 1) x 30 + 300 | G6: =(B6-1)*30+300 -> 630 | H6: =IF(G6=E6,"yes","no") -> yes | I6: Same pattern as TOT: one step higher in QDMR.
A7: VOX Level | B7: =Comparison!H69 -> 0 | C7: 0 = off, 1-5 = level | D7: =IF(B7=0,"Off",B7) -> Off | E7: 1 | F7: raw + 1 | G7: =B7+1 -> 1 | H7: =IF(G7=E7,"yes","no") -> yes | I7: The factory shows levels 1-5 for raw 0-4, so QDMR reading 0 as "off" looks like a misreading.
A8: Analog MIC Level | B8: =Comparison!H74 -> 4 | C8: raw x 10 / 5 + 1 (scale 1-10) | D8: =INT(B8*10/5)+1 -> 9 | E8: 5 | F8: raw + 1 | G8: =B8+1 -> 5 | H8: =IF(G8=E8,"yes","no") -> yes | I8: QDMR rescales 0-4 to 1-10; the factory shows raw + 1.
A9: Digital MIC Level | B9: =Comparison!H75 -> 3 | C9: raw x 10 / 5 + 1 (scale 1-10) | D9: =INT(B9*10/5)+1 -> 7 | E9: 4 | F9: raw + 1 | G9: =B9+1 -> 4 | H9: =IF(G9=E9,"yes","no") -> yes | I9: Same as the analog mic level.
A10: Backlight Brightness | B10: =Comparison!H24 -> 4 | C10: raw x 10 / 5 (scale 1-10) | D10: =INT(B10*10/5) -> 8 | E10: 5 | F10: raw + 1 | G10: =B10+1 -> 5 | H10: =IF(G10=E10,"yes","no") -> yes | I10: QDMR rescales 0-4 to a 10-point scale; the factory shows raw + 1.
A11: Time Zone (hours from UTC) | B11: =Comparison!H35 -> 20 | C11: raw - 11 | D11: =B11-11 -> 9 | E11: 8 | F11: raw - 12 | G11: =B11-12 -> 8 | H11: =IF(G11=E11,"yes","no") -> yes | I11: QDMR is one hour higher than the factory CPS.
A13: Settings with text values
A14: Setting | B14: Raw value | C14: QDMR reads as | D14: Factory CPS shows | E14: Note
A15: GPS Switch | B15: =Comparison!H33 -> 1 | C15: On | D15: Unchecked | E15: Raw bit is set; the factory box is empty.
A16: GPS Mode | B16: =Comparison!H34 -> 1 | C16: Beidou | D16: GPS+BDS | E16: Raw 1 is Beidou in QDMR but GPS+BDS in the factory CPS.
A17: Work Mode(A) | B17: =Comparison!H58 -> 1 | C17: VFO | D17: MR | E17: Raw 1 is VFO in QDMR but MR (channel mode) in the factory CPS.
A18: Work Mode(B) | B18: =Comparison!H59 -> 1 | C18: VFO | D18: MR | E18: Same as Work Mode(A).
A19: Main Channel Setting | B19: =Comparison!H62 -> 1 | C19: B | D19: A | E19: Raw 1 is B in QDMR but A in the factory CPS.

Sheet Round trip
A1: Does QDMR change these values when it reads and writes them back?
A2: Calculated with the same range-mapping formula QDMR uses (integer arithmetic). "Same?" = yes means the raw byte comes back unchanged.
A4: Setting | B4: Raw value on radio | C4: Level QDMR holds | D4: Raw value written back | E4: Same?
A5: Mic level (raw 0-4 mapped to 1-10) | B5: 0 | C5: =INT(B5*10/5)+1 -> 1 | D5: =INT((C5-1)*5/10) -> 0 | E5: =IF(D5=B5,"yes","no") -> yes
A6: Mic level (raw 0-4 mapped to 1-10) | B6: 1 | C6: =INT(B6*10/5)+1 -> 3 | D6: =INT((C6-1)*5/10) -> 1 | E6: =IF(D6=B6,"yes","no") -> yes
A7: Mic level (raw 0-4 mapped to 1-10) | B7: 2 | C7: =INT(B7*10/5)+1 -> 5 | D7: =INT((C7-1)*5/10) -> 2 | E7: =IF(D7=B7,"yes","no") -> yes
A8: Mic level (raw 0-4 mapped to 1-10) | B8: 3 | C8: =INT(B8*10/5)+1 -> 7 | D8: =INT((C8-1)*5/10) -> 3 | E8: =IF(D8=B8,"yes","no") -> yes
A9: Mic level (raw 0-4 mapped to 1-10) | B9: 4 | C9: =INT(B9*10/5)+1 -> 9 | D9: =INT((C9-1)*5/10) -> 4 | E9: =IF(D9=B9,"yes","no") -> yes
A10: VOX level (raw 1-5 mapped to 1-10) | B10: 1 | C10: =INT((B10-1)*10/5)+1 -> 1 | D10: =INT((C10-1)*5/10)+1 -> 1 | E10: =IF(D10=B10,"yes","no") -> yes
A11: VOX level (raw 1-5 mapped to 1-10) | B11: 2 | C11: =INT((B11-1)*10/5)+1 -> 3 | D11: =INT((C11-1)*5/10)+1 -> 2 | E11: =IF(D11=B11,"yes","no") -> yes
A12: VOX level (raw 1-5 mapped to 1-10) | B12: 3 | C12: =INT((B12-1)*10/5)+1 -> 5 | D12: =INT((C12-1)*5/10)+1 -> 3 | E12: =IF(D12=B12,"yes","no") -> yes
A13: VOX level (raw 1-5 mapped to 1-10) | B13: 4 | C13: =INT((B13-1)*10/5)+1 -> 7 | D13: =INT((C13-1)*5/10)+1 -> 4 | E13: =IF(D13=B13,"yes","no") -> yes
A14: VOX level (raw 1-5 mapped to 1-10) | B14: 5 | C14: =INT((B14-1)*10/5)+1 -> 9 | D14: =INT((C14-1)*5/10)+1 -> 5 | E14: =IF(D14=B14,"yes","no") -> yes
A15: TOT (your radio: raw 22) | B15: =Comparison!H67 -> 22 | C15: =B15*5+15 -> 125 | D15: =(C15-15)/5 -> 22 | E15: =IF(D15=B15,"yes","no") -> yes
A17: Active Wait Time, Backlight, Time Zone and GPS are not written by QDMR at all, so they are not round-tripped. Only values QDMR both reads and writes are shown.
